Error: 

ServiceFault (BadIdentityTokenInvalid, diagnostics: DiagnosticInfo(SymbolicId=None, NamespaceURI=None, Locale=None, LocalizedText=None, AdditionalInfo=None, InnerStatusCode=None, InnerDiagnosticInfo=None)) from server received  in response to ActivateSessionRequest
Traceback (most recent call last):
  File "C:\Users\te542932\Desktop\Machines-connectie-karakteristieken\OpcuaSoftwareNodeDYS\Python_GUI_client_OPCUA\simple_main_version.py", line 34, in <module>
    asyncio.run(main())
  File "C:\Users\te542932\AppData\Local\Programs\Python\Python311\Lib\asyncio\runners.py", line 190, in run
    return runner.run(main)
           ^^^^^^^^^^^^^^^^
  File "C:\Users\te542932\AppData\Local\Programs\Python\Python311\Lib\asyncio\runners.py", line 118, in run
    return self._loop.run_until_complete(task)
           ^^^^^^^^^^^^^^^^^^^^^^^^^^^^^^^^^^^
  File "C:\Users\te542932\AppData\Local\Programs\Python\Python311\Lib\asyncio\base_events.py", line 653, in run_until_complete
    return future.result()
           ^^^^^^^^^^^^^^^
  File "C:\Users\te542932\Desktop\Machines-connectie-karakteristieken\OpcuaSoftwareNodeDYS\Python_GUI_client_OPCUA\simple_main_version.py", line 12, in main
    async with Client(url=url) as client:
  File "C:\Users\te542932\AppData\Local\Programs\Python\Python311\Lib\site-packages\asyncua\client\client.py", line 86, in __aenter__
    await self.connect()
  File "C:\Users\te542932\AppData\Local\Programs\Python\Python311\Lib\site-packages\asyncua\client\client.py", line 282, in connect
    await self.activate_session(username=self._username, password=self._password, certificate=self.user_certificate)
  File "C:\Users\te542932\AppData\Local\Programs\Python\Python311\Lib\site-packages\asyncua\client\client.py", line 537, in activate_session
    return await self.uaclient.activate_session(params)
           ^^^^^^^^^^^^^^^^^^^^^^^^^^^^^^^^^^^^^^^^^^^^
  File "C:\Users\te542932\AppData\Local\Programs\Python\Python311\Lib\site-packages\asyncua\client\ua_client.py", line 339, in activate_session
    data = await self.protocol.send_request(request)
           ^^^^^^^^^^^^^^^^^^^^^^^^^^^^^^^^^^^^^^^^^
  File "C:\Users\te542932\AppData\Local\Programs\Python\Python311\Lib\site-packages\asyncua\client\ua_client.py", line 165, in send_request
    self.check_answer(data, f" in response to {request.__class__.__name__}")
  File "C:\Users\te542932\AppData\Local\Programs\Python\Python311\Lib\site-packages\asyncua\client\ua_client.py", line 174, in check_answer
    hdr.ServiceResult.check()
  File "C:\Users\te542932\AppData\Local\Programs\Python\Python311\Lib\site-packages\asyncua\ua\uatypes.py", line 328, in check
    raise UaStatusCodeError(self.value)
asyncua.ua.uaerrors._auto.BadIdentityTokenInvalid: "The user identity token is not valid."(BadIdentityTokenInvalid)